Workbook

Sheet crm_data
A1: =IFERROR(__xludf.DUMMYFUNCTION("IMPORTRANGE(""https://docs.google.com/spreadsheets/d/1JA61vI-6je-zfvXewBSeLRLJ7tn_aDncp6iyXTcRkgg/edit?usp=sharing"", ""CRM_Database!A1:E101"")"),"ID") -> ID | B1: =IFERROR(__xludf.DUMMYFUNCTION("""COMPUTED_VALUE"""),"Ім’я") -> Ім’я | C1: =IFERROR(__xludf.DUMMYFUNCTION("""COMPUTED_VALUE"""),"Місто") -> Місто | D1: =IFERROR(__xludf.DUMMYFUNCTION("""COMPUTED_VALUE"""),"Статус") -> Статус | E1: =IFERROR(__xludf.DUMMYFUNCTION("""COMPUTED_VALUE"""),"Канал") -> Канал
A2: =IFERROR(__xludf.DUMMYFUNCTION("""COMPUTED_VALUE"""),1001.0) -> 1001 | B2: =IFERROR(__xludf.DUMMYFUNCTION("""COMPUTED_VALUE"""),"Марина") -> Марина | C2: =IFERROR(__xludf.DUMMYFUNCTION("""COMPUTED_VALUE"""),"Київ") -> Київ | D2: =IFERROR(__xludf.DUMMYFUNCTION("""COMPUTED_VALUE"""),"Активний") -> Активний | E2: =IFERROR(__xludf.DUMMYFUNCTION("""COMPUTED_VALUE"""),"Instagram") -> Instagram
A3: =IFERROR(__xludf.DUMMYFUNCTION("""COMPUTED_VALUE"""),1002.0) -> 1002 | B3: =IFERROR(__xludf.DUMMYFUNCTION("""COMPUTED_VALUE"""),"Андрій") -> Андрій | C3: =IFERROR(__xludf.DUMMYFUNCTION("""COMPUTED_VALUE"""),"Львів") -> Львів | D3: =IFERROR(__xludf.DUMMYFUNCTION("""COMPUTED_VALUE"""),"Потенційний") -> Потенційний | E3: =IFERROR(__xludf.DUMMYFUNCTION("""COMPUTED_VALUE"""),"Facebook") -> Facebook
A4: =IFERROR(__xludf.DUMMYFUNCTION("""COMPUTED_VALUE"""),1003.0) -> 1003 | B4: =IFERROR(__xludf.DUMMYFUNCTION("""COMPUTED_VALUE"""),"Олена") -> Олена | C4: =IFERROR(__xludf.DUMMYFUNCTION("""COMPUTED_VALUE"""),"Одеса") -> Одеса | D4: =IFERROR(__xludf.DUMMYFUNCTION("""COMPUTED_VALUE"""),"Неактивний") -> Неактивний | E4: =IFERROR(__xludf.DUMMYFUNCTION("""COMPUTED_VALUE"""),"Email") -> Email
A5: =IFERROR(__xludf.DUMMYFUNCTION("""COMPUTED_VALUE"""),1004.0) -> 1004 | B5: =IFERROR(__xludf.DUMMYFUNCTION("""COMPUTED_VALUE"""),"Тетяна") -> Тетяна | C5: =IFERROR(__xludf.DUMMYFUNCTION("""COMPUTED_VALUE"""),"Харків") -> Харків | D5: =IFERROR(__xludf.DUMMYFUNCTION("""COMPUTED_VALUE"""),"Активний") -> Активний | E5: =IFERROR(__xludf.DUMMYFUNCTION("""COMPUTED_VALUE"""),"Google Ads") -> Google Ads
A6: =IFERROR(__xludf.DUMMYFUNCTION("""COMPUTED_VALUE"""),1005.0) -> 1005 | B6: =IFERROR(__xludf.DUMMYFUNCTION("""COMPUTED_VALUE"""),"Дмитро") -> Дмитро | C6: =IFERROR(__xludf.DUMMYFUNCTION("""COMPUTED_VALUE"""),"Дніпро") -> Дніпро | D6: =IFERROR(__xludf.DUMMYFUNCTION("""COMPUTED_VALUE"""),"Потенційний") -> Потенційний | E6: =IFERROR(__xludf.DUMMYFUNCTION("""COMPUTED_VALUE"""),"YouTube") -> YouTube
A7: =IFERROR(__xludf.DUMMYFUNCTION("""COMPUTED_VALUE"""),1006.0) -> 1006 | B7: =IFERROR(__xludf.DUMMYFUNCTION("""COMPUTED_VALUE"""),"Сергій") -> Сергій | C7: =IFERROR(__xludf.DUMMYFUNCTION("""COMPUTED_VALUE"""),"Вінниця") -> Вінниця | D7: =IFERROR(__xludf.DUMMYFUNCTION("""COMPUTED_VALUE"""),"Неактивний") -> Неактивний | E7: =IFERROR(__xludf.DUMMYFUNCTION("""COMPUTED_VALUE"""),"TikTok") -> TikTok
A8: =IFERROR(__xludf.DUMMYFUNCTION("""COMPUTED_VALUE"""),1007.0) -> 1007 | B8: =IFERROR(__xludf.DUMMYFUNCTION("""COMPUTED_VALUE"""),"Юлія") -> Юлія | C8: =IFERROR(__xludf.DUMMYFUNCTION("""COMPUTED_VALUE"""),"Запоріжжя") -> Запоріжжя | D8: =IFERROR(__xludf.DUMMYFUNCTION("""COMPUTED_VALUE"""),"Активний") -> Активний | E8: =IFERROR(__xludf.DUMMYFUNCTION("""COMPUTED_VALUE"""),"Instagram") -> Instagram
A9: =IFERROR(__xludf.DUMMYFUNCTION("""COMPUTED_VALUE"""),1008.0) -> 1008 | B9: =IFERROR(__xludf.DUMMYFUNCTION("""COMPUTED_VALUE"""),"Назар") -> Назар | C9: =IFERROR(__xludf.DUMMYFUNCTION("""COMPUTED_VALUE"""),"Полтава") -> Полтава | D9: =IFERROR(__xludf.DUMMYFUNCTION("""COMPUTED_VALUE"""),"Потенційний") -> Потенційний | E9: =IFERROR(__xludf.DUMMYFUNCTION("""COMPUTED_VALUE"""),"Facebook") -> Facebook
A10: =IFERROR(__xludf.DUMMYFUNCTION("""COMPUTED_VALUE"""),1009.0) -> 1009 | B10: =IFERROR(__xludf.DUMMYFUNCTION("""COMPUTED_VALUE"""),"Ірина") -> Ірина | C10: =IFERROR(__xludf.DUMMYFUNCTION("""COMPUTED_VALUE"""),"Черкаси") -> Черкаси | D10: =IFERROR(__xludf.DUMMYFUNCTION("""COMPUTED_VALUE"""),"Неактивний") -> Неактивний | E10: =IFERROR(__xludf.DUMMYFUNCTION("""COMPUTED_VALUE"""),"Email") -> Email
A11: =IFERROR(__xludf.DUMMYFUNCTION("""COMPUTED_VALUE"""),1010.0) -> 1010 | B11: =IFERROR(__xludf.DUMMYFUNCTION("""COMPUTED_VALUE"""),"Богдан") -> Богдан | C11: =IFERROR(__xludf.DUMMYFUNCTION("""COMPUTED_VALUE"""),"Ужгород") -> Ужгород | D11: =IFERROR(__xludf.DUMMYFUNCTION("""COMPUTED_VALUE"""),"Активний") -> Активний | E11: =IFERROR(__xludf.DUMMYFUNCTION("""COMPUTED_VALUE"""),"Google Ads") -> Google Ads
A12: =IFERROR(__xludf.DUMMYFUNCTION("""COMPUTED_VALUE"""),1011.0) -> 1011 | B12: =IFERROR(__xludf.DUMMYFUNCTION("""COMPUTED_VALUE"""),"Анастасія") -> Анастасія | C12: =IFERROR(__xludf.DUMMYFUNCTION("""COMPUTED_VALUE"""),"Київ") -> Київ | D12: =IFERROR(__xludf.DUMMYFUNCTION("""COMPUTED_VALUE"""),"Потенційний") -> Потенційний | E12: =IFERROR(__xludf.DUMMYFUNCTION("""COMPUTED_VALUE"""),"YouTube") -> YouTube
A13: =IFERROR(__xludf.DUMMYFUNCTION("""COMPUTED_VALUE"""),1012.0) -> 1012 | B13: =IFERROR(__xludf.DUMMYFUNCTION("""COMPUTED_VALUE"""),"Максим") -> Максим | C13: =IFERROR(__xludf.DUMMYFUNCTION("""COMPUTED_VALUE"""),"Львів") -> Львів | D13: =IFERROR(__xludf.DUMMYFUNCTION("""COMPUTED_VALUE"""),"Неактивний") -> Неактивний | E13: =IFERROR(__xludf.DUMMYFUNCTION("""COMPUTED_VALUE"""),"TikTok") -> TikTok
A14: =IFERROR(__xludf.DUMMYFUNCTION("""COMPUTED_VALUE"""),1013.0) -> 1013 | B14: =IFERROR(__xludf.DUMMYFUNCTION("""COMPUTED_VALUE"""),"Анна") -> Анна | C14: =IFERROR(__xludf.DUMMYFUNCTION("""COMPUTED_VALUE"""),"Одеса") -> Одеса | D14: =IFERROR(__xludf.DUMMYFUNCTION("""COMPUTED_VALUE"""),"Активний") -> Активний | E14: =IFERROR(__xludf.DUMMYFUNCTION("""COMPUTED_VALUE"""),"Instagram") -> Instagram
A15: =IFERROR(__xludf.DUMMYFUNCTION("""COMPUTED_VALUE"""),1014.0) -> 1014 | B15: =IFERROR(__xludf.DUMMYFUNCTION("""COMPUTED_VALUE"""),"Артем") -> Артем | C15: =IFERROR(__xludf.DUMMYFUNCTION("""COMPUTED_VALUE"""),"Харків") -> Харків | D15: =IFERROR(__xludf.DUMMYFUNCTION("""COMPUTED_VALUE"""),"Потенційний") -> Потенційний | E15: =IFERROR(__xludf.DUMMYFUNCTION("""COMPUTED_VALUE"""),"Facebook") -> Facebook
A16: =IFERROR(__xludf.DUMMYFUNCTION("""COMPUTED_VALUE"""),1015.0) -> 1015 | B16: =IFERROR(__xludf.DUMMYFUNCTION("""COMPUTED_VALUE"""),"Олександр") -> Олександр | C16: =IFERROR(__xludf.DUMMYFUNCTION("""COMPUTED_VALUE"""),"Дніпро") -> Дніпро | D16: =IFERROR(__xludf.DUMMYFUNCTION("""COMPUTED_VALUE"""),"Неактивний") -> Неактивний | E16: =IFERROR(__xludf.DUMMYFUNCTION("""COMPUTED_VALUE"""),"Email") -> Email
A17: =IFERROR(__xludf.DUMMYFUNCTION("""COMPUTED_VALUE"""),1016.0) -> 1016 | B17: =IFERROR(__xludf.DUMMYFUNCTION("""COMPUTED_VALUE"""),"Катерина") -> Катерина | C17: =IFERROR(__xludf.DUMMYFUNCTION("""COMPUTED_VALUE"""),"Вінниця") -> Вінниця | D17: =IFERROR(__xludf.DUMMYFUNCTION("""COMPUTED_VALUE"""),"Активний") -> Активний | E17: =IFERROR(__xludf.DUMMYFUNCTION("""COMPUTED_VALUE"""),"Google Ads") -> Google Ads
A18: =IFERROR(__xludf.DUMMYFUNCTION("""COMPUTED_VALUE"""),1017.0) -> 1017 | B18: =IFERROR(__xludf.DUMMYFUNCTION("""COMPUTED_VALUE"""),"Віктор") -> Віктор | C18: =IFERROR(__xludf.DUMMYFUNCTION("""COMPUTED_VALUE"""),"Запоріжжя") -> Запоріжжя | D18: =IFERROR(__xludf.DUMMYFUNCTION("""COMPUTED_VALUE"""),"Потенційний") -> Потенційний | E18: =IFERROR(__xludf.DUMMYFUNCTION("""COMPUTED_VALUE"""),"YouTube") -> YouTube
A19: =IFERROR(__xludf.DUMMYFUNCTION("""COMPUTED_VALUE"""),1018.0) -> 1018 | B19: =IFERROR(__xludf.DUMMYFUNCTION("""COMPUTED_VALUE"""),"Алла") -> Алла | C19: =IFERROR(__xludf.DUMMYFUNCTION("""COMPUTED_VALUE"""),"Полтава") -> Полтава | D19: =IFERROR(__xludf.DUMMYFUNCTION("""COMPUTED_VALUE"""),"Неактивний") -> Неактивний | E19: =IFERROR(__xludf.DUMMYFUNCTION("""COMPUTED_VALUE"""),"TikTok") -> TikTok
A20: =IFERROR(__xludf.DUMMYFUNCTION("""COMPUTED_VALUE"""),1019.0) -> 1019 | B20: =IFERROR(__xludf.DUMMYFUNCTION("""COMPUTED_VALUE"""),"Ярослав") -> Ярослав | C20: =IFERROR(__xludf.DUMMYFUNCTION("""COMPUTED_VALUE"""),"Черкаси") -> Черкаси | D20: =IFERROR(__xludf.DUMMYFUNCTION("""COMPUTED_VALUE"""),"Активний") -> Активний | E20: =IFERROR(__xludf.DUMMYFUNCTION("""COMPUTED_VALUE"""),"Instagram") -> Instagram
A21: =IFERROR(__xludf.DUMMYFUNCTION("""COMPUTED_VALUE"""),1020.0) -> 1020 | B21: =IFERROR(__xludf.DUMMYFUNCTION("""COMPUTED_VALUE"""),"Роман") -> Роман | C21: =IFERROR(__xludf.DUMMYFUNCTION("""COMPUTED_VALUE"""),"Ужгород") -> Ужгород | D21: =IFERROR(__xludf.DUMMYFUNCTION("""COMPUTED_VALUE"""),"Потенційний") -> Потенційний | E21: =IFERROR(__xludf.DUMMYFUNCTION("""COMPUTED_VALUE"""),"Facebook") -> Facebook
A22: =IFERROR(__xludf.DUMMYFUNCTION("""COMPUTED_VALUE"""),1021.0) -> 1021 | B22: =IFERROR(__xludf.DUMMYFUNCTION("""COMPUTED_VALUE"""),"Олег") -> Олег | C22: =IFERROR(__xludf.DUMMYFUNCTION("""COMPUTED_VALUE"""),"Київ") -> Київ | D22: =IFERROR(__xludf.DUMMYFUNCTION("""COMPUTED_VALUE"""),"Неактивний") -> Неактивний | E22: =IFERROR(__xludf.DUMMYFUNCTION("""COMPUTED_VALUE"""),"Email") -> Email
A23: =IFERROR(__xludf.DUMMYFUNCTION("""COMPUTED_VALUE"""),1022.0) -> 1022 | B23: =IFERROR(__xludf.DUMMYFUNCTION("""COMPUTED_VALUE"""),"Світлана") -> Світлана | C23: =IFERROR(__xludf.DUMMYFUNCTION("""COMPUTED_VALUE"""),"Львів") -> Львів | D23: =IFERROR(__xludf.DUMMYFUNCTION("""COMPUTED_VALUE"""),"Активний") -> Активний | E23: =IFERROR(__xludf.DUMMYFUNCTION("""COMPUTED_VALUE"""),"Google Ads") -> Google Ads
A24: =IFERROR(__xludf.DUMMYFUNCTION("""COMPUTED_VALUE"""),1023.0) -> 1023 | B24: =IFERROR(__xludf.DUMMYFUNCTION("""COMPUTED_VALUE"""),"Жанна") -> Жанна | C24: =IFERROR(__xludf.DUMMYFUNCTION("""COMPUTED_VALUE"""),"Одеса") -> Одеса | D24: =IFERROR(__xludf.DUMMYFUNCTION("""COMPUTED_VALUE"""),"Потенційний") -> Потенційний | E24: =IFERROR(__xludf.DUMMYFUNCTION("""COMPUTED_VALUE"""),"YouTube") -> YouTube
A25: =IFERROR(__xludf.DUMMYFUNCTION("""COMPUTED_VALUE"""),1024.0) -> 1024 | B25: =IFERROR(__xludf.DUMMYFUNCTION("""COMPUTED_VALUE"""),"Ігор") -> Ігор | C25: =IFERROR(__xludf.DUMMYFUNCTION("""COMPUTED_VALUE"""),"Харків") -> Харків | D25: =IFERROR(__xludf.DUMMYFUNCTION("""COMPUTED_VALUE"""),"Неактивний") -> Неактивний | E25: =IFERROR(__xludf.DUMMYFUNCTION("""COMPUTED_VALUE"""),"TikTok") -> TikTok
A26: =IFERROR(__xludf.DUMMYFUNCTION("""COMPUTED_VALUE"""),1025.0) -> 1025 | B26: =IFERROR(__xludf.DUMMYFUNCTION("""COMPUTED_VALUE"""),"Зоряна") -> Зоряна | C26: =IFERROR(__xludf.DUMMYFUNCTION("""COMPUTED_VALUE"""),"Дніпро") -> Дніпро | D26: =IFERROR(__xludf.DUMMYFUNCTION("""COMPUTED_VALUE"""),"Активний") -> Активний | E26: =IFERROR(__xludf.DUMMYFUNCTION("""COMPUTED_VALUE"""),"Instagram") -> Instagram
A27: =IFERROR(__xludf.DUMMYFUNCTION("""COMPUTED_VALUE"""),1026.0) -> 1026 | B27: =IFERROR(__xludf.DUMMYFUNCTION("""COMPUTED_VALUE"""),"Руслан") -> Руслан | C27: =IFERROR(__xludf.DUMMYFUNCTION("""COMPUTED_VALUE"""),"Вінниця") -> Вінниця | D27: =IFERROR(__xludf.DUMMYFUNCTION("""COMPUTED_VALUE"""),"Потенційний") -> Потенційний | E27: =IFERROR(__xludf.DUMMYFUNCTION("""COMPUTED_VALUE"""),"Facebook") -> Facebook
A28: =IFERROR(__xludf.DUMMYFUNCTION("""COMPUTED_VALUE"""),1027.0) -> 1027 | B28: =IFERROR(__xludf.DUMMYFUNCTION("""COMPUTED_VALUE"""),"Марта") -> Марта | C28: =IFERROR(__xludf.DUMMYFUNCTION("""COMPUTED_VALUE"""),"Запоріжжя") -> Запоріжжя | D28: =IFERROR(__xludf.DUMMYFUNCTION("""COMPUTED_VALUE"""),"Неактивний") -> Неактивний | E28: =IFERROR(__xludf.DUMMYFUNCTION("""COMPUTED_VALUE"""),"Email") -> Email
A29: =IFERROR(__xludf.DUMMYFUNCTION("""COMPUTED_VALUE"""),1028.0) -> 1028 | B29: =IFERROR(__xludf.DUMMYFUNCTION("""COMPUTED_VALUE"""),"Микита") -> Микита | C29: =IFERROR(__xludf.DUMMYFUNCTION("""COMPUTED_VALUE"""),"Полтава") -> Полтава | D29: =IFERROR(__xludf.DUMMYFUNCTION("""COMPUTED_VALUE"""),"Активний") -> Активний | E29: =IFERROR(__xludf.DUMMYFUNCTION("""COMPUTED_VALUE"""),"Google Ads") -> Google Ads
A30: =IFERROR(__xludf.DUMMYFUNCTION("""COMPUTED_VALUE"""),1029.0) -> 1029 | B30: =IFERROR(__xludf.DUMMYFUNCTION("""COMPUTED_VALUE"""),"Дарина") -> Дарина | C30: =IFERROR(__xludf.DUMMYFUNCTION("""COMPUTED_VALUE"""),"Черкаси") -> Черкаси | D30: =IFERROR(__xludf.DUMMYFUNCTION("""COMPUTED_VALUE"""),"Потенційний") -> Потенційний | E30: =IFERROR(__xludf.DUMMYFUNCTION("""COMPUTED_VALUE"""),"YouTube") -> YouTube
A31: =IFERROR(__xludf.DUMMYFUNCTION("""COMPUTED_VALUE"""),1030.0) -> 1030 | B31: =IFERROR(__xludf.DUMMYFUNCTION("""COMPUTED_VALUE"""),"Євген") -> Євген | C31: =IFERROR(__xludf.DUMMYFUNCTION("""COMPUTED_VALUE"""),"Ужгород") -> Ужгород | D31: =IFERROR(__xludf.DUMMYFUNCTION("""COMPUTED_VALUE"""),"Неактивний") -> Неактивний | E31: =IFERROR(__xludf.DUMMYFUNCTION("""COMPUTED_VALUE"""),"TikTok") -> TikTok
A32: =IFERROR(__xludf.DUMMYFUNCTION("""COMPUTED_VALUE"""),1031.0) -> 1031 | B32: =IFERROR(__xludf.DUMMYFUNCTION("""COMPUTED_VALUE"""),"Наталія") -> Наталія | C32: =IFERROR(__xludf.DUMMYFUNCTION("""COMPUTED_VALUE"""),"Київ") -> Київ | D32: =IFERROR(__xludf.DUMMYFUNCTION("""COMPUTED_VALUE"""),"Активний") -> Активний | E32: =IFERROR(__xludf.DUMMYFUNCTION("""COMPUTED_VALUE"""),"Instagram") -> Instagram
A33: =IFERROR(__xludf.DUMMYFUNCTION("""COMPUTED_VALUE"""),1032.0) -> 1032 | B33: =IFERROR(__xludf.DUMMYFUNCTION("""COMPUTED_VALUE"""),"Владислав") -> Владислав | C33: =IFERROR(__xludf.DUMMYFUNCTION("""COMPUTED_VALUE"""),"Львів") -> Львів | D33: =IFERROR(__xludf.DUMMYFUNCTION("""COMPUTED_VALUE"""),"Потенційний") -> Потенційний | E33: =IFERROR(__xludf.DUMMYFUNCTION("""COMPUTED_VALUE"""),"Facebook") -> Facebook
A34: =IFERROR(__xludf.DUMMYFUNCTION("""COMPUTED_VALUE"""),1033.0) -> 1033 | B34: =IFERROR(__xludf.DUMMYFUNCTION("""COMPUTED_VALUE"""),"Софія") -> Софія | C34: =IFERROR(__xludf.DUMMYFUNCTION("""COMPUTED_VALUE"""),"Одеса") -> Одеса | D34: =IFERROR(__xludf.DUMMYFUNCTION("""COMPUTED_VALUE"""),"Неактивний") -> Неактивний | E34: =IFERROR(__xludf.DUMMYFUNCTION("""COMPUTED_VALUE"""),"Email") -> Email
A35: =IFERROR(__xludf.DUMMYFUNCTION("""COMPUTED_VALUE"""),1034.0) -> 1034 | B35: =IFERROR(__xludf.DUMMYFUNCTION("""COMPUTED_VALUE"""),"Ілля") -> Ілля | C35: =IFERROR(__xludf.DUMMYFUNCTION("""COMPUTED_VALUE"""),"Харків") -> Харків | D35: =IFERROR(__xludf.DUMMYFUNCTION("""COMPUTED_VALUE"""),"Активний") -> Активний | E35: =IFERROR(__xludf.DUMMYFUNCTION("""COMPUTED_VALUE"""),"Google Ads") -> Google Ads
A36: =IFERROR(__xludf.DUMMYFUNCTION("""COMPUTED_VALUE"""),1035.0) -> 1035 | B36: =IFERROR(__xludf.DUMMYFUNCTION("""COMPUTED_VALUE"""),"Тимур") -> Тимур | C36: =IFERROR(__xludf.DUMMYFUNCTION("""COMPUTED_VALUE"""),"Дніпро") -> Дніпро | D36: =IFERROR(__xludf.DUMMYFUNCTION("""COMPUTED_VALUE"""),"Потенційний") -> Потенційний | E36: =IFERROR(__xludf.DUMMYFUNCTION("""COMPUTED_VALUE"""),"YouTube") -> YouTube
A37: =IFERROR(__xludf.DUMMYFUNCTION("""COMPUTED_VALUE"""),1036.0) -> 1036 | B37: =IFERROR(__xludf.DUMMYFUNCTION("""COMPUTED_VALUE"""),"Вероніка") -> Вероніка | C37: =IFERROR(__xludf.DUMMYFUNCTION("""COMPUTED_VALUE"""),"Вінниця") -> Вінниця | D37: =IFERROR(__xludf.DUMMYFUNCTION("""COMPUTED_VALUE"""),"Неактивний") -> Неактивний | E37: =IFERROR(__xludf.DUMMYFUNCTION("""COMPUTED_VALUE"""),"TikTok") -> TikTok
A38: =IFERROR(__xludf.DUMMYFUNCTION("""COMPUTED_VALUE"""),1037.0) -> 1037 | B38: =IFERROR(__xludf.DUMMYFUNCTION("""COMPUTED_VALUE"""),"Леся") -> Леся | C38: =IFERROR(__xludf.DUMMYFUNCTION("""COMPUTED_VALUE"""),"Запоріжжя") -> Запоріжжя | D38: =IFERROR(__xludf.DUMMYFUNCTION("""COMPUTED_VALUE"""),"Активний") -> Активний | E38: =IFERROR(__xludf.DUMMYFUNCTION("""COMPUTED_VALUE"""),"Instagram") -> Instagram
A39: =IFERROR(__xludf.DUMMYFUNCTION("""COMPUTED_VALUE"""),1038.0) -> 1038 | B39: =IFERROR(__xludf.DUMMYFUNCTION("""COMPUTED_VALUE"""),"Павло") -> Павло | C39: =IFERROR(__xludf.DUMMYFUNCTION("""COMPUTED_VALUE"""),"Полтава") -> Полтава | D39: =IFERROR(__xludf.DUMMYFUNCTION("""COMPUTED_VALUE"""),"Потенційний") -> Потенційний | E39: =IFERROR(__xludf.DUMMYFUNCTION("""COMPUTED_VALUE"""),"Facebook") -> Facebook
A40: =IFERROR(__xludf.DUMMYFUNCTION("""COMPUTED_VALUE"""),1039.0) -> 1039 | B40: =IFERROR(__xludf.DUMMYFUNCTION("""COMPUTED_VALUE"""),"Яна") -> Яна | C40: =IFERROR(__xludf.DUMMYFUNCTION("""COMPUTED_VALUE"""),"Черкаси") -> Черкаси | D40: =IFERROR(__xludf.DUMMYFUNCTION("""COMPUTED_VALUE"""),"Неактивний") -> Неактивний | E40: =IFERROR(__xludf.DUMMYFUNCTION("""COMPUTED_VALUE"""),"Email") -> Email
...

Sheet clients_tracker
A1: client_name | B1: status_from_crm | C1: channel_from_crm | D1: crm_position
A2: Дмитро | B2: =VLOOKUP($A2,crm_data!$B$1:$E$101,3,0) -> Потенційний | C2: =VLOOKUP($A2,crm_data!$B$1:$E$101,4,0) -> YouTube | D2: =MATCH($A2,crm_data!$B$2:$B997,0) -> 5
A3: Артем | B3: =VLOOKUP($A3,crm_data!$B$1:$E$101,3,0) -> Потенційний | C3: =VLOOKUP($A3,crm_data!$B$1:$E$101,4,0) -> Facebook | D3: =MATCH($A3,crm_data!$B$2:$B997,0) -> 14
A4: Марта | B4: =VLOOKUP($A4,crm_data!$B$1:$E$101,3,0) -> Неактивний | C4: =VLOOKUP($A4,crm_data!$B$1:$E$101,4,0) -> Email | D4: =MATCH($A4,crm_data!$B$2:$B997,0) -> 27
A5: Алла | B5: =VLOOKUP($A5,crm_data!$B$1:$E$101,3,0) -> Неактивний | C5: =VLOOKUP($A5,crm_data!$B$1:$E$101,4,0) -> TikTok | D5: =MATCH($A5,crm_data!$B$2:$B997,0) -> 18
A6: Юрій | B6: =VLOOKUP($A6,crm_data!$B$1:$E$101,3,0) -> Активний | C6: =VLOOKUP($A6,crm_data!$B$1:$E$101,4,0) -> Google Ads | D6: =MATCH($A6,crm_data!$B$2:$B997,0) -> 46

Sheet notes_log
A1: 45919.409 | B1: Кирило | C1: Потенційний
A2: 45919.41 | B2: Зоряна | C2: Активний
A3: 45919.411 | B3: Вікторія | C3: Неактивний
A4: 45919.412 | B4: Дмитро | C4: Потенційний
A5: 45919.412 | B5: Артем | C5: Потенційний
A6: 45919.412 | B6: Марта | C6: Неактивний
A7: 45919.412 | B7: Арсен | C7: Потенційний
A8: 45919.412 | B8: Микита | C8: Активний
A9: 45919.413 | B9: Алла | C9: Неактивний
