Workbook

Sheet raw_data
A1: user_id | B1: sessions | C1: payments | D1: game_time_minutes
A2: 1d60048e | B2: 8 | C2: 1 | D2: 142
A3: 811a2f2a | B3: 4 | C3: 68.06 | D3: 113.6
A4: 6e68de94 | B4: 2 | C4: 3.95 | D4: 139.6
A5: 7b235456 | B5: 3 | C5: 13.79 | D5: 105.8
A6: 8337899e | B6: 4 | C6: 16.43 | D6: 190.5
A7: 759a5069 | B7: 7 | C7: 19.52 | D7: 40.1
A8: 4c9d013e | B8: 4 | C8: 60.44 | D8: 140.2
A9: 4026f24f | B9: 3 | C9: 2.76 | D9: 67.1
A10: 669e8315 | B10: 2 | C10: 0.41 | D10: 113.2
A11: 0d88ee75 | B11: 6 | C11: 5.3 | D11: 117.4
A12: e2378c6f | B12: 3 | C12: 1.39 | D12: 165.2
A13: 6b94e85b | B13: 5 | C13: 0.23 | D13: 99.2
... A43: 28df8147 | B43: 6 | C43: 2.38 | D43: 117.6
A44: 13628710 | B44: 2 | C44: 54.33 | D44: 114.5
A45: 6932221e | B45: 4 | C45: 39.7 | D45: 120.9
A46: ef7d7144 | B46: 7 | C46: 10.48 | D46: 99.7
A47: 1fb2537c | B47: 6 | C47: 16.32 | D47: 150.1
A48: 101f5728 | B48: 5 | C48: 12.56 | D48: 122.9
A49: ecdd3e5b | B49: 4 | C49: 8.99 | D49: 104.9
A50: 43ec3229 | B50: 3 | C50: 0.55 | D50: 130.3
A51: c96b54b8 | B51: 3 | C51: 6.07 | D51: 117.8
A52: 85a21042 | B52: 7 | C52: 11.23 | D52: 68
A53: 1d80c16e | B53: 7 | C53: 11.32 | D53: 130.2
A54: 840d59a0 | B54: 6 | C54: 4.67 | D54: 89.4
A55: db7b71c7 | B55: 6 | C55: 28.42 | D55: 148
A56: 493feba2 | B56: 7 | C56: 1.83 | D56: 112.7
... A91: 4cb06a50 | B91: 5 | C91: 0.88 | D91: 110.2
A92: 65451583 | B92: 2 | C92: 9.34 | D92: 110.6
A93: e9d203ef | B93: 6 | C93: 21.28 | D93: 138.3
A94: 753ed5f5 | B94: 4 | C94: 21.45 | D94: 105.9
A95: 3eee8e3f | B95: 3 | C95: 10.76 | D95: 77.2
A96: ee6ec3d7 | B96: 5 | C96: 2.37 | D96: 142.8
A97: 18b298ce | B97: 6 | C97: 19.88 | D97: 85.6
A98: c796bc91 | B98: 3 | C98: 21.72 | D98: 135.5
A99: b73546ef | B99: 4 | C99: 2.19 | D99: 149.2
A100: 65d0ee1a | B100: 8 | C100: 13.37 | D100: 108.7
A101: 829d5df7 | B101: 4 | C101: 3.38 | D101: 155.5
A102: b10848b2 | B102: 10 | C102: 16.23 | D102: 134.5
A103: a2a45a90 | B103: 4 | C103: 58.92 | D103: 99.1
...

Sheet raw_data_edited
A1: user_id | B1: sessions | C1: payments | D1: game_time_minutes | E1: payment_outlier
A2: 1d60048e | B2: 8 | C2: 1 | D2: 142 | E2: =if(C2>statistics_analysis!$C$15,"high outlier",if(C2<statistics_analysis!$C$14,"low outlier","normal")) -> normal
A3: 811a2f2a | B3: 4 | C3: 68.06 | D3: 113.6 | E3: =if(C3>statistics_analysis!$C$15,"high outlier",if(C3<statistics_analysis!$C$14,"low outlier","normal")) -> high outlier
A4: 6e68de94 | B4: 2 | C4: 3.95 | D4: 139.6 | E4: =if(C4>statistics_analysis!$C$15,"high outlier",if(C4<statistics_analysis!$C$14,"low outlier","normal")) -> normal
A5: 7b235456 | B5: 3 | C5: 13.79 | D5: 105.8 | E5: =if(C5>statistics_analysis!$C$15,"high outlier",if(C5<statistics_analysis!$C$14,"low outlier","normal")) -> normal
A6: 8337899e | B6: 4 | C6: 16.43 | D6: 190.5 | E6: =if(C6>statistics_analysis!$C$15,"high outlier",if(C6<statistics_analysis!$C$14,"low outlier","normal")) -> normal
A7: 759a5069 | B7: 7 | C7: 19.52 | D7: 40.1 | E7: =if(C7>statistics_analysis!$C$15,"high outlier",if(C7<statistics_analysis!$C$14,"low outlier","normal")) -> normal
A8: 4c9d013e | B8: 4 | C8: 60.44 | D8: 140.2 | E8: =if(C8>statistics_analysis!$C$15,"high outlier",if(C8<statistics_analysis!$C$14,"low outlier","normal")) -> high outlier
A9: 4026f24f | B9: 3 | C9: 2.76 | D9: 67.1 | E9: =if(C9>statistics_analysis!$C$15,"high outlier",if(C9<statistics_analysis!$C$14,"low outlier","normal")) -> normal
A10: 669e8315 | B10: 2 | C10: 0.41 | D10: 113.2 | E10: =if(C10>statistics_analysis!$C$15,"high outlier",if(C10<statistics_analysis!$C$14,"low outlier","normal")) -> normal
A11: 0d88ee75 | B11: 6 | C11: 5.3 | D11: 117.4 | E11: =if(C11>statistics_analysis!$C$15,"high outlier",if(C11<statistics_analysis!$C$14,"low outlier","normal")) -> normal
A12: e2378c6f | B12: 3 | C12: 1.39 | D12: 165.2 | E12: =if(C12>statistics_analysis!$C$15,"high outlier",if(C12<statistics_analysis!$C$14,"low outlier","normal")) -> normal
A13: 6b94e85b | B13: 5 | C13: 0.23 | D13: 99.2 | E13: =if(C13>statistics_analysis!$C$15,"high outlier",if(C13<statistics_analysis!$C$14,"low outlier","normal")) -> normal
... A43: 28df8147 | B43: 6 | C43: 2.38 | D43: 117.6 | E43: =if(C43>statistics_analysis!$C$15,"high outlier",if(C43<statistics_analysis!$C$14,"low outlier","normal")) -> normal
A44: 13628710 | B44: 2 | C44: 54.33 | D44: 114.5 | E44: =if(C44>statistics_analysis!$C$15,"high outlier",if(C44<statistics_analysis!$C$14,"low outlier","normal")) -> high outlier
A45: 6932221e | B45: 4 | C45: 39.7 | D45: 120.9 | E45: =if(C45>statistics_analysis!$C$15,"high outlier",if(C45<statistics_analysis!$C$14,"low outlier","normal")) -> high outlier
A46: ef7d7144 | B46: 7 | C46: 10.48 | D46: 99.7 | E46: =if(C46>statistics_analysis!$C$15,"high outlier",if(C46<statistics_analysis!$C$14,"low outlier","normal")) -> normal
A47: 1fb2537c | B47: 6 | C47: 16.32 | D47: 150.1 | E47: =if(C47>statistics_analysis!$C$15,"high outlier",if(C47<statistics_analysis!$C$14,"low outlier","normal")) -> normal
A48: 101f5728 | B48: 5 | C48: 12.56 | D48: 122.9 | E48: =if(C48>statistics_analysis!$C$15,"high outlier",if(C48<statistics_analysis!$C$14,"low outlier","normal")) -> normal
A49: ecdd3e5b | B49: 4 | C49: 8.99 | D49: 104.9 | E49: =if(C49>statistics_analysis!$C$15,"high outlier",if(C49<statistics_analysis!$C$14,"low outlier","normal")) -> normal
A50: 43ec3229 | B50: 3 | C50: 0.55 | D50: 130.3 | E50: =if(C50>statistics_analysis!$C$15,"high outlier",if(C50<statistics_analysis!$C$14,"low outlier","normal")) -> normal
A51: c96b54b8 | B51: 3 | C51: 6.07 | D51: 117.8 | E51: =if(C51>statistics_analysis!$C$15,"high outlier",if(C51<statistics_analysis!$C$14,"low outlier","normal")) -> normal
A52: 85a21042 | B52: 7 | C52: 11.23 | D52: 68 | E52: =if(C52>statistics_analysis!$C$15,"high outlier",if(C52<statistics_analysis!$C$14,"low outlier","normal")) -> normal
A53: 1d80c16e | B53: 7 | C53: 11.32 | D53: 130.2 | E53: =if(C53>statistics_analysis!$C$15,"high outlier",if(C53<statistics_analysis!$C$14,"low outlier","normal")) -> normal
A54: 840d59a0 | B54: 6 | C54: 4.67 | D54: 89.4 | E54: =if(C54>statistics_analysis!$C$15,"high outlier",if(C54<statistics_analysis!$C$14,"low outlier","normal")) -> normal
A55: db7b71c7 | B55: 6 | C55: 28.42 | D55: 148 | E55: =if(C55>statistics_analysis!$C$15,"high outlier",if(C55<statistics_analysis!$C$14,"low outlier","normal")) -> normal
A56: 493feba2 | B56: 7 | C56: 1.83 | D56: 112.7 | E56: =if(C56>statistics_analysis!$C$15,"high outlier",if(C56<statistics_analysis!$C$14,"low outlier","normal")) -> normal
... A91: 4cb06a50 | B91: 5 | C91: 0.88 | D91: 110.2 | E91: =if(C91>statistics_analysis!$C$15,"high outlier",if(C91<statistics_analysis!$C$14,"low outlier","normal")) -> normal
A92: 65451583 | B92: 2 | C92: 9.34 | D92: 110.6 | E92: =if(C92>statistics_analysis!$C$15,"high outlier",if(C92<statistics_analysis!$C$14,"low outlier","normal")) -> normal
A93: e9d203ef | B93: 6 | C93: 21.28 | D93: 138.3 | E93: =if(C93>statistics_analysis!$C$15,"high outlier",if(C93<statistics_analysis!$C$14,"low outlier","normal")) -> normal
A94: 753ed5f5 | B94: 4 | C94: 21.45 | D94: 105.9 | E94: =if(C94>statistics_analysis!$C$15,"high outlier",if(C94<statistics_analysis!$C$14,"low outlier","normal")) -> normal
A95: 3eee8e3f | B95: 3 | C95: 10.76 | D95: 77.2 | E95: =if(C95>statistics_analysis!$C$15,"high outlier",if(C95<statistics_analysis!$C$14,"low outlier","normal")) -> normal
A96: ee6ec3d7 | B96: 5 | C96: 2.37 | D96: 142.8 | E96: =if(C96>statistics_analysis!$C$15,"high outlier",if(C96<statistics_analysis!$C$14,"low outlier","normal")) -> normal
A97: 18b298ce | B97: 6 | C97: 19.88 | D97: 85.6 | E97: =if(C97>statistics_analysis!$C$15,"high outlier",if(C97<statistics_analysis!$C$14,"low outlier","normal")) -> normal
A98: c796bc91 | B98: 3 | C98: 21.72 | D98: 135.5 | E98: =if(C98>statistics_analysis!$C$15,"high outlier",if(C98<statistics_analysis!$C$14,"low outlier","normal")) -> normal
A99: b73546ef | B99: 4 | C99: 2.19 | D99: 149.2 | E99: =if(C99>statistics_analysis!$C$15,"high outlier",if(C99<statistics_analysis!$C$14,"low outlier","normal")) -> normal
A100: 65d0ee1a | B100: 8 | C100: 13.37 | D100: 108.7 | E100: =if(C100>statistics_analysis!$C$15,"high outlier",if(C100<statistics_analysis!$C$14,"low outlier","normal")) -> normal
A101: 829d5df7 | B101: 4 | C101: 3.38 | D101: 155.5 | E101: =if(C101>statistics_analysis!$C$15,"high outlier",if(C101<statistics_analysis!$C$14,"low outlier","normal")) -> normal
A102: b10848b2 | B102: 10 | C102: 16.23 | D102: 134.5 | E102: =if(C102>statistics_analysis!$C$15,"high outlier",if(C102<statistics_analysis!$C$14,"low outlier","normal")) -> normal
A103: a2a45a90 | B103: 4 | C103: 58.92 | D103: 99.1 | E103: =if(C103>statistics_analysis!$C$15,"high outlier",if(C103<statistics_analysis!$C$14,"low outlier","normal")) -> high outlier
...

Sheet statistics_analysis
B1: sessions | C1: payments | D1: game_time_minutes | F1: Побудова діаграми
A2: AVG | B2: =AVERAGE(raw_data!B2:B501) -> 4.974 | C2: =AVERAGE(raw_data!C2:C501) -> 10.06386 | D2: =AVERAGE(raw_data!D2:D501) -> 119.9864 | F2: Побудова таблиці для гістограми за payment_outlier через COUNTIF.
A3: MED | B3: =MEDIAN(raw_data!B2:B501) -> 5 | C3: =MEDIAN(raw_data!C2:C501) -> 6.71 | D3: =MEDIAN(raw_data!D2:D501) -> 119.55 | F3: high outlier | G3: =countif(raw_data_edited!$E$2:$E$501,F3) -> 23
A4: MOD | B4: =MODE(raw_data!B2:B501) -> 4 | C4: =MODE(raw_data!C2:C501) -> 4.38 | D4: =MODE(raw_data!D2:D501) -> 109.2 | F4: normal | G4: =countif(raw_data_edited!$E$2:$E$501,F4) -> 477
A5: MIN | B5: =min(raw_data!B2:B501) -> 0 | C5: =min(raw_data!C2:C501) -> 0.01 | D5: =min(raw_data!D2:D501) -> 40.1
A6: MAX | B6: =MAX(raw_data!B2:B501) -> 12 | C6: =MAX(raw_data!C2:C501) -> 77.24 | D6: =MAX(raw_data!D2:D501) -> 203 | F6: Виявлено 23 викиди, тобто значення payments, що перевищують верхню межу (30.91), відповідно вони впливають на середнє значення (завищують)
A7: STDEV | B7: =STDEV(raw_data!B2:B501) -> 2.2617593 | C7: =STDEV(raw_data!C2:C501) -> 10.402668 | D7: =STDEV(raw_data!D2:D501) -> 30.98328
A9: Q1 | B9: =QUARTILE(raw_data!B2:B501,1) -> 3 | C9: =QUARTILE(raw_data!C2:C501,1) -> 2.8125 | D9: =QUARTILE(raw_data!D2:D501,1) -> 99.025
A10: Q2 (медіана) | B10: =QUARTILE(raw_data!B2:B501,2) -> 5 | C10: =QUARTILE(raw_data!C2:C501,2) -> 6.71 | D10: =QUARTILE(raw_data!D2:D501,2) -> 119.55
A11: Q3 | B11: =QUARTILE(raw_data!B2:B501,3) -> 6 | C11: =QUARTILE(raw_data!C2:C501,3) -> 14.05 | D11: =QUARTILE(raw_data!D2:D501,3) -> 141.15
A12: IQR | B12: =B11-B9 -> 3 | C12: =C11-C9 -> 11.2375 | D12: =D11-D9 -> 42.125
A14: Нижня межа | B14: =B9-1.5*B12 -> -1.5 | C14: =C9-1.5*C12 -> -14.04375 | D14: =D9-1.5*D12 -> 35.8375
A15: Верхня межа | B15: =B11+1.5*B12 -> 10.5 | C15: =C11+1.5*C12 -> 30.90625 | D15: =D11+1.5*D12 -> 204.3375
B16: *якщо не ціле значення - округлення до сотих(напр. 0,01)
F20: Дані по sessions розподілені рівно, середнє приблизно дорівнює медіані, дані розташовані в нормальних межах
E35: MIN | F35: Q1 | G35: MED | H35: Q3 | I35: MAX
D36: sessions | E36: 0 | F36: =B9 -> 3 | G36: 5 | H36: =B11 -> 6 | I36: =B6 -> 12

Sheet explanation
A1: Яке середнє значення payments? | B1: =statistics_analysis!C2 -> 10.06386
A2: Чи відрізняється воно від медіани? | B2: Так
A3: Скільки викидів знайдено? | B3: 23
A4: Скільки — високих? | B4: Всі високі викиди
A5: Який користувач оплатив найбільше? | B5: 574bcaca
A6: Який висновок ти можеш дати з побудовних діаграм розподілу значень? | B6: З побудованої діаграми по payments видно, що більшість значень (477) лежать у нормальних межах, а незначна кількість (23) є викидами. Викиди є високими та можуть спотворювати середнє значення.
A7: Чи впливають ці викиди на середнє? | B7: Так, середнє значно перевищує медіану. Це свідчить, що наявність високих викидів завищує середнє, і воно не відображає типове значення для більшості даних. Медіана у цьому випадку точніше відображає загальну тенденцію.
A8: Як це може вплинути на звітність або бізнес-рішення? | B8: Викиди у даних про оплати гравців можуть спотворювати середні показники доходу, створюючи хибне враження про типові витрати. Це може призвести до помилкових бізнес-рішень, наприклад, завищених прогнозів доходу або некоректних маркетингових стратегій. Тому важливо аналізувати високі та аномальні платежі окремо, щоб ухвалювати точніші рішення.
